<?xml version="1.0"?>
<robot xmlns:xacro="http://www.ros.org/wiki/xacro" name="wheel">
      <xacro:macro name="wheel" params="prefix x y z roll:=0 pitch:=0 yaw:=0 x_reflect:=1 y_reflect:=1">
        <link name="${prefix}_link">
          <visual>
            <origin xyz="0 0 0" rpy="${pi/2} 0 0"/>
            <geometry>
                <cylinder radius="${wheel_radius}" length="${wheel_width}"/>
            </geometry>
            <material name="Gray">
              <color rgba="0.5 0.5 0.5 1.0"/>
            </material>
          </visual>

          <collision>
            <origin xyz="0 0 0" rpy="${pi/2} 0 0"/>
            <geometry>
                <cylinder radius="${wheel_radius}" length="${wheel_width}"/>
            </geometry>
          </collision>
          
          <!-- 
          <surface>
            <friction>
              <ode>
                <mu>0.01</mu>
                <mu2>0.01</mu2>
              </ode>
            </friction>
          </surface> 
          -->
          
          <xacro:cylinder_inertia m="0.5" r="${wheel_radius}" h="${wheel_width}"/>
        </link>

        <joint name="${prefix}_joint" type="continuous">
          <parent link="base_link"/>
          <child link="${prefix}_link"/>
          <origin xyz="${x_reflect*x} ${y_reflect*y} ${z}" rpy="${roll} ${pitch} ${yaw}"/>
          <axis xyz="0 1 0"/>
        </joint>
      </xacro:macro>
</robot>